<?xml version="1.0"?>
<robot xmlns:xacro="http://ros.org/wiki/xacro" >
<xacro:include filename="$(find fishbot_description)/urdf/fishbot/common_inertia.xacro"/>
   
    
    <!-- 机器人imu部件，惯性测量传感器 -->
    <xacro:macro name="wheel_xacro" params='wheel_name xyz'> 
    <link name="${wheel_name}_link">
        <visual>
          <!-- 要把轮子竖起来所以u修改偏移量 -->
            <origin xyz="0.0 0.0 0.0" rpy="1.57079 0.0 0.0"/>                
        <!-- 几何形状 -->
            <geometry>
            <!-- 圆柱体 -->
               <cylinder radius="0.032" length="0.01"/>
            </geometry>
            <!-- 材质颜色 -->
            <material name="yellow">
                <color rgba="1.0 1.0 0.0 0.8"/>
            </material>
        </visual>
        <collision>
             <!-- 要把轮子竖起来所以u修改偏移量 -->
            <origin xyz="0.0 0.0 0.0" rpy="1.57079 0.0 0.0"/>                
        <!-- 几何形状 -->
            <geometry>
            <!-- 圆柱体 -->
               <cylinder radius="0.032" length="0.01"/>
            </geometry>
            <!-- 材质颜色 -->
            <material name="yellow">
                <color rgba="1.0 1.0 0.0 0.8"/>
            </material>
        </collision>

        <xacro:cylinder_inertia m="0.05" r="0.032" h ="0.01" />

    </link>
    <!-- 机器人关节，用于组合机器人的部件 -->
         <joint name="${wheel_name}_joint" type="continuous">
            <parent link="base_link"/>
            <child link="${wheel_name}_link"/>
            <origin xyz="${xyz}" rpy="0.0 0.0 0.0"/>
            <!-- 表示围绕y轴旋转 -->
            <axis xyz="0.0 1.0 0.0"/>

        </joint>
        <!-- 设置轮子摩擦力  这些标签分别代表了 摩擦系数，刚度系数 ，阻尼系数  imu1：且向摩擦系数，imu2：fa向摩擦系数 kp;接触的刚度系数,kd：接触的阻尼系数-->
        <gazebo reference = "${wheel_name}_link">
            <imu1 value = "20.0"/>
            <imu2 value = "20.0"/>
            <kp value="10000000000.0"/>
            <kd value="1.0"/>

        </gazebo>
    </xacro:macro>

     


</robot>
